Workbook
Name __________A466666: #REF!
Name _________A466666: #REF!
Name ________A466666: #REF!
Name _______A466666: #REF!
Name ______A466666: #REF!
Name _____A466666: #REF!
Name ____A466666: #REF!
Name ___A466666: #REF!
Name __A466666: #REF!
Name _1년이하_200811: #REF!
Name _1년이하_해외현지__200811: #REF!
Name _2년이하_200811: #REF!
Name _2년이하_해외현지__200811: #REF!
Name _2년초과_200811: #REF!
Name _2년초과_해외현지__200811: #REF!
Name _3개월이하_200811: #REF!
Name _3개월이하_해외현지__200811: #REF!
Name _6개월이하_200811: #REF!
Name _6개월이하_해외현지__200811: #REF!
Name _A466666: #REF!
Name aa: #REF!
Name aaa: [3]!aaa
Name aaaa: [3]!aaaa
Name ActualRange: #REF!
Name agdump: #REF!
Name agedump: #REF!
Name agencydump: #REF!
Name AGENCYLY: #REF!
Name AGENCYPLAN: #REF!
Name asa: [3]!asa
Name asas: [3]!asas
Name bsNote: [3]!bsNote
Name btnClose: [3]!btnClose
Name btnFootNoting: [3]!btnFootNoting
Name btnNext: [3]!btnNext
Name btnOK: [3]!btnOK
Name btnPrevious: [3]!btnPrevious
Name btnReturn: [3]!btnReturn
Name CalcAgencyPrice: #REF!
Name cash: [3]!cash
Name CashFlow_Button1_Click: [3]!CashFlow_Button1_Click
Name cashIndex: [3]!cashIndex
Name ccc: #REF!
Name Commission: #REF!
Name dada: [3]!dada
Name DaRWk1: #REF!
Name DaRWk10: #REF!
Name DaRWk11: #REF!
Name DaRWk12: #REF!
Name DaRWk2: #REF!
Name DaRWk3: #REF!
Name DaRWk4: #REF!
Name DaRWk5: #REF!
Name DaRWk6: #REF!
Name DaRWk8: #REF!
Name DaRwk9: #REF!
Name data: [4]data!$A:$T
Name DaWk7: #REF!
Name dbase: #REF!
Name dbrwk1: #REF!

Sheet AC 금융조회서 control sheet
A1: 코스맥스비티아이 주식회사
A2: 금융조회서 control sheet
A3: 46022
B5: 조서번호 | C5: 금융기관 | D5: 지점 | E5: 조회(*1) | F5: 주소 | H5: 담당자 | I5: 전화번호 | J5: 회신(*2)
B6: BC-1 | C6: 국민은행 | E6: 온라인 조회 | J6: 원본
B7: BC-2 | C7: 중소기업은행 | E7: 온라인 조회 | J7: 원본
B8: BC-3 | C8: 우리은행 | E8: 온라인 조회 | J8: 원본
B9: BC-4 | C9: 하나은행 | E9: 온라인 조회 | J9: 원본
B10: BC-5 | C10: 신한은행 | E10: 온라인 조회 | J10: 원본
B11: BC-6 | C11: 산업은행 | E11: 온라인 조회 | J11: 원본
B12: BC-7 | C12: 대구은행 | E12: 온라인 조회 | J12: 원본
B13: BC-8 | C13: 한국수출입은행 | E13: 온라인 조회 | J13: 원본
B14: BC-9 | C14: 한국증권금융 | E14: 온라인 조회 | J14: 원본
B15: BC-10 | C15: 대신증권 | E15: 온라인 조회 | J15: 원본
B16: BC-11 | C16: 메리츠증권 | D16: 광화문금융센터 | E16: 온라인 조회 | J16: 원본
B17: BC-12 | C17: 신한금융투자 | D17: 강남대로금융센터 | E17: 온라인 조회 | J17: 원본
B18: BC-13 | C18: KB증권 | D18: 송파 | E18: 온라인 조회 | J18: 원본
B19: BC-14 | C19: NH투자증권 | D19: 농협재단Ｂ | E19: 온라인 조회 | J19: 원본
B20: BC-15 | C20: 삼성증권 | D20: 잠실ＷＭ | E20: 온라인 조회 | J20: 원본
B21: BC-16 | C21: 미래에셋증권 | D21: ＷＭ 강남파이낸스센 | E21: 온라인 조회 | J21: 원본
B22: BC-17 | C22: 키움증권 | D22: 영업부 | E22: 온라인 조회 | J22: 원본
B23: BC-18 | C23: 한화투자증권 | D23: 송파지점 | E23: 온라인 조회 | J23: 원본
B24: BC-19 | C24: KB손해보험 | D24: 본사 | E24: 온라인 조회 | J24: 원본
B25: BC-20 | C25: 한화손해보험 | D25: 본사 | E25: 온라인 조회 | J25: 원본
B26: BC-21 | C26: 메리츠화재해상보험 | D26: 고객지원파트 | E26: 온라인 조회 | J26: 원본
B27: BC-22 | C27: 서울보증보험 | D27: 성남 | E27: 온라인 조회 | J27: 원본
B28: BC-23 | C28: 농협은행 | E28: 온라인 조회 | J28: 원본
B29: BC-24 | C29: 현대해상보험 | D29: 사무지원실 | E29: 온라인 조회 | J29: 원본
B30: BC-30 | C30: 흥국화재 | E30: 우편 조회 | F30: 서울시 종로구 새문안로 68 흥국빌딩 4층 소비자지원팀 | H30: 김가은 | I30: 02-2002-6822 | J30: 원본
B31: BC-25 | C31: 예별손해보험 | D31: 소비자보호실 소비자지원팀 | E31: 우편 조회 | F31: 서울시 강남구 테헤란로 335 예별손해보험 12층 | H31: 이승연 차장 | I31: 02-3788-2402 | J31: 원본
B32: BC-26 | C32: SHB Hongkong IB Center | E32: 우편 조회 | F32: Unit 7704, 77/F., International Commerce Centre, No.1 Austin Road West, Kowloon, Hong Kong | H32: Elaine Ho | I32: +852 3717 0707 | J32: 원본
B33: BC-27 | C33: 국민은행 홍콩 | E33: 우편 조회 | F33: 1101 and 1106, 11/F, Central Plaza, 18 Harbour Road, wanchai, Hong Kong | H33: 이현근 과장 | I33: +852 2103 9947 | J33: 원본
B34: BC-28 | C34: 국민은행 런던지점 | E34: 우편 조회 | F34: Kookmin Bank London branch, 15th Floor, Dashwood House, 69 Old Broad | H34: 김영우대리님 | I34: +44 (0)2033273810 | J34: 원본 | L34: Unit 7704, 77/F., International Commerce Centre, No. 1 Austin Road West, Kowloon, Hong Kong T : +852 3737 0700 F : +852 2810 1426 | W34: elaine@shinhanhk.com
B35: BC-29 | C35: ㈜카일이삼제스퍼 | E35: 우편 조회 | F35: 서울시 서초구 명달로9, 방배빌딩 6층, 카일이삼 | H35: 김수빈 | I35: 010-2473-2581 | J35: 원본 | L35: 1101 and 1106, 11/F, Central Plaza, 18 Harbour Road, Wanchai, Hong Kong T : (852) 2103 9958 F : (852) 2869 6650 | W35: douglas.chan@kbfg.com
B41: (*1) 조회 형태는 온라인조회와 우편조회로 구분하고, 온라인조회의 경우 주소 정보는 별도로 기입할 필요 없음

Sheet AC0. 금융조회 대상 완전성 검토
A1: 코스맥스비티아이 주식회사 | E1: 작성자: 김웅 | G1: 일자: | I1: 조서번호
A2: 금융조회 대상의 완전성 검토 | E2: 검토자: 이병기 | G2: 일자: | I2: AC0
A3: 46022
A5: 1. 감사목적
B6: 금융조회 대상의 완전성 확인
A8: 2. 감사절차
B9: 1) 회사로부터 기말 잔액 여부와 관계없이 기중 거래가 있었던 모든 금융기관의 list 징구
B10: 2) 1)의 회사 제시 금융기관 list와 전기 금융조회 대상의 비교 및 변동이 있는 경우 그 사유 파악
C11: 전기 금융조회 대상 | D11: 회사 제시 list 포함? | E11: 제외사유 및 타당성 검토
C12: 국민은행 | D12: Y
C13: 중소기업은행 | D13: Y
C14: 우리은행 | D14: Y
C15: 하나은행 | D15: Y
C16: 신한은행 | D16: Y
C17: 산업은행 | D17: Y
C18: 대구은행 | D18: Y
C19: 한국수출입은행 | D19: Y
C20: 한국증권금융 | D20: Y
C21: 대신증권 | D21: Y
C22: 메리츠증권 | D22: Y
C23: 신한금융투자 | D23: Y
... C44: MG손해보험 | D44: N
B46: 3) 2025년 12월말 은행연합회 월보상 금융기관이 회사 제시 금융기관 list에 누락되었는지 확인 후, 누락된 경우 그 사유 파악
C47: 은행연합회 월보 | D47: 회사 제시 list 포함? | E47: 제외사유 및 타당성 검토
C48: 산업은행 | D48: Y
C49: 수출입은행 | D49: Y
C50: 국민은행 | D50: Y
C51: 신한은행 | D51: Y
C52: 하나은행 | D52: Y
C53: 서울보증보험 | D53: Y
C54: 한화투자증권 | D54: Y
C55: 한국증권금융 | D55: Y
C56: NH투자증권 | D56: Y
C57: 농협은행 | D57: Y
B68: 4) 예금, 차입금, 이자수익, 이자비용 등의 금융기관 관련 계정별 원장 검토 및 담보제공내역, 지급보증 내역 등의 명세서 검토를 통해 회사 거래
B69: 금융기관을 확인 후 회사 제시 금융기관 list에 누락됨이 없는지 확인
C70: ① 계정별원장 검토
C71: 구분 | D71: 계정별원장상 금융기관 | E71: 회사 제시 list 포함? | F71: 제외사유 및 타당성 검토
C72: 이자비용(차입금) | D72: 기업은행 | E72: Y
C73: 수수료(금융수수료) | D73: SHINHAN BANK HK IB CENTER | E73: Y
...

Sheet AC1~AC8 금융조회서 요약 ->

Sheet AC1. 금융자산
A1: ='AC 금융조회서 control sheet'!A1 -> 코스맥스비티아이 주식회사 | I1: 작성자: | K1: 일자: | M1: 조서번호
A2: 금융조회서 요약(1) - 금융자산 | I2: 검토자: | K2: 일자: | M2: AC1
A3: 46022
A5: 1. 감사목적
B6: 회사의 금융자산 실재성 검토
A8: 2. 감사절차
B9: 1) 금융조회서상 회사의 금융자산을 요약 정리함
C10: 조서번호 | D10: 금융기관명 | E10: 금융상품 종류 | F10: 계좌번호 | G10: 통화 | H10: 금액 | I10: 이자율 | J10: 최종이자지급일 | K10: 만기일 | L10: 인출제한 등 | M10: 회사 계정과목명 | N10: 수량 | O10: 액면금액 | P10: 기준가 | Q10: 평가액 | R10: 비고
C11: BC-1 | D11: 국민은행 | E11: KB기업종합통장-보통예금 | F11: 09360101005744 | G11: KRW | H11: 0 | I11: 0.0000 | J11: 20190615 | K11: 00000000 | L11: '
E12: 사업자응원통장-보통예금 | F12: 09360101044822 | G12: KRW | H12: 10218 | I12: 0.0000 | J12: 20251213 | K12: 00000000 | L12: '
E13: ONE KB 사업자통장-보통예금 | F13: 09360101055020 | G13: KRW | H13: 308755 | I13: 0.0000 | J13: 20251213 | K13: 00000000 | L13: '
E14: KB우대기업자유-기업자유 | F14: 09363704003056 | G14: KRW | H14: 0 | I14: 0.0000 | J14: 20251213 | K14: 00000000
E15: KB연구비통장-기업자유 | F15: 09363704006651 | G15: KRW | H15: 0 | I15: 0.0000 | J15: 00000000 | K15: 00000000
E16: 외화보통예금 | F16: 09366811000804 | G16: USD | H16: 0 | I16: 0.0000 | J16: 20211112 | K16: 00000000
E17: 외화보통예금 | F17: 09366811004828 | G17: USD | H17: 0 | I17: 0.0000 | J17: 20201113 | K17: 00000000
E18: KB기업종합통장-보통예금 | F18: 236010263385 | G18: KRW | H18: 0 | I18: 0.0000 | J18: 20251213 | K18: 00000000
E19: 일반당좌예금 | F19: 236040001456 | G19: KRW | H19: 0 | I19: 0.0000 | J19: 00000000 | K19: 00000000 | L19: '
E20: 당좌개설보증금 | F20: 0936127300000019 | G20: KRW | H20: 1500000 | I20: 0.0000 | J20: 00000000 | K20: 00000000 | L20: '
E21: 퇴직연금 | F21: 11138900010672 | G21: KRW | H21: 126,598,004.00(126,645,985.00) | I21: 0.0000 | J21: 00000000 | K21: 00000000 | L21: '
C22: BC-2 | D22: 기업은행 | E22: 당좌예금 | F22: 25700072806032 | G22: KRW | H22: 0 | I22: ' | J22: 00000000 | K22: 00000000 | L22: '
E23: 기업금전 | F23: 25700072872018 | G23: KRW | H23: 0 | I23: ' | J23: 19940923 | K23: 00000000 | L23: '
E24: 기업자유 | F24: 25700072804088 | G24: KRW | H24: 0 | I24: ' | J24: 20251221 | K24: 00000000
E25: 퇴직연금 | F25: 25700072894004 | G25: KRW | H25: 503905003 | I25: ' | J25: 00000000 | K25: 00000000
E26: 고수익기업 | F26: 25700072804095 | G26: KRW | H26: 0 | I26: ' | J26: 20251221 | K26: 00000000
E27: 기업자유 | F27: 25700072804106 | G27: KRW | H27: 8002500 | I27: ' | J27: 20251221 | K27: 00000000
E28: 보통예금 | F28: 25712326201019 | G28: KRW | H28: 0 | I28: ' | J28: 20251214 | K28: 00000000
E29: 기업자유 | F29: 54900001104015 | G29: KRW | H29: 0 | I29: ' | J29: 20251221 | K29: 00000000
E30: 외화보통 | F30: 2570007285600031 | G30: USD | H30: 0 | I30: ' | J30: 20251228 | K30: 00000000
E31: 수익증권 | F31: 25700072896005 | G31: KRW | H31: 0 | I31: 배당지급 | J31: 20140625 | K31: 00000000 | L31: '
E32: 당좌개설보증금 | F32: ' | G32: KRW | H32: 3000000 | I32: ' | J32: 00000000 | K32: 00000000 | L32: '
C33: BC-3 | D33: 우리은행 | E33: 기업자유예금 | F33: 1005002697408 | G33: KRW | H33: 0 | I33: 0.0000 | J33: 20251219 | K33: 00010101 | L33: '
E34: 기업자유예금 | F34: 1005202449762 | G34: KRW | H34: 0 | I34: 0.0000 | J34: 20251219 | K34: 00010101
E35: 기업자유예금 | F35: 1005403574235 | G35: KRW | H35: 27 | I35: 0.0000 | J35: 20251219 | K35: 00010101
E36: 기업자유예금 | F36: 1005800182976 | G36: KRW | I36: 0.0000 | J36: 20251219 | K36: 00010101
E37: 보통예금 | F37: 1006801233951 | G37: KRW | H37: 0 | I37: 0.0000 | J37: 20251219 | K37: 00010101
E38: 외화보통예금 | F38: 1081000553090 | G38: CNY | H38: 0 | I38: 0.0000 | J38: 20251220 | K38: 00010101
E39: 외화보통예금 | F39: 1081000553090 | G39: USD | H39: 0 | I39: 0.0000 | J39: 20251220 | K39: 00010101
E40: 외화보통예금 | F40: 1081500773095 | G40: EUR | H40: 0 | I40: 0.0000 | J40: 20251220 | K40: 00010101
E41: 외화보통예금 | F41: 1081500773095 | G41: USD | H41: 0 | I41: 0.0000 | J41: 20251220 | K41: 00010101
E42: 퇴직연금신탁(DB) | F42: 1121200429393 | G42: KRW | H42: 727,414,231.00(727,414,231.00) | I42: 0.0000 | J42: 20251230 | K42: 00010101
...

Sheet AC2. 차입금
A1: ='AC 금융조회서 control sheet'!A1 -> 코스맥스비티아이 주식회사 | L1: 작성자: | N1: 일자: | P1: 조서번호
A2: 금융조회서 요약(2) - 차입금 | L2: 검토자: | N2: 일자: | P2: AC2
A3: 46022
A5: 1. 감사목적
B6: 회사의 차입금 완전성 검토
A8: 2. 감사절차
B9: 1) 금융조회서상 회사의 차입금을 요약 정리함
C10: 조서번호 | D10: 금융기관명 | E10: 대출종류 | F10: 한도 | H10: 대출 | P10: 회사 계정과목명
F11: 통화 | G11: 한도금액 | H11: 통화 | I11: 대출금액 | J11: 대출일 | K11: 최종만기일 | L11: 연이자율 | M11: 최종이자지급일 | N11: 상환방법 | O11: 담보 보증 및 관련 약정
C12: BC-1 | D12: 국민은행 | E12: 기업일반운전자금대출 | F12: KRW | G12: 0.00 | H12: KRW | I12: 14,500,000,000.00 | J12: 20250610 | K12: 20260610 | L12: 4.5000 | M12: 20251210 | N12: 일시상환 | O12: 9번항목참조
E13: 외상매출채권전자대출(순)_상환청구권 | F13: KRW | G13: 1,000,000,000.00 | H13: KRW | I13: 18,720,900.00 | J13: 20200612 | K13: 20260605 | L13: 0.0000 | M13: 20260303 | N13: 일시상환 | O13: 9번항목참조
E14: 기업일반운전자금대출 | F14: KRW | G14: 5,000,000,000.00 | H14: KRW | I14: 0.00 | J14: 20210219 | K14: 20260213 | L14: 4.6600 | M14: 20251219 | N14: 일시상환 | O14: 9번항목참조
E15: 기업일반운전자금대출 | F15: KRW | G15: 3,000,000,000.00 | H15: KRW | I15: 0.00 | J15: 20250707 | K15: 20260707 | L15: 4.7100 | M15: 20251224 | N15: 일시상환 | O15: 9번항목참조
C16: BC-3 | D16: 우리은행 | E16: B2B PLUS 대출 기업운전외상 | F16: KRW | G16: 0 | H16: KRW | I16: 0 | J16: 20090625 | K16: 20260703 | L16: 0.0000 | M16: 20090723 | N16: 만기일시상환 | O16: '
E17: B2B PLUS 대출 기업운전외상 | F17: KRW | G17: 0 | H17: KRW | I17: 0 | J17: 20030820 | K17: 20260430 | L17: 0.0000 | M17: 20041228 | N17: 만기일시상환 | O17: '
E18: B2B PLUS 대출 기업운전외상 | F18: KRW | G18: 0 | H18: KRW | I18: 0 | J18: 20090731 | K18: 20260529 | L18: 0.0000 | M18: 20120101 | N18: 만기일시상환 | O18: '
C19: BC-4 | D19: 하나은행 | E19: 기업시설일반자금대출 | F19: KRW | G19: 7000000000 | H19: KRW | I19: 7000000000 | J19: 20140616 | K19: 20260716 | L19: 3.815 | M19: 00000000 | N19: 만기일시상환 | O19: 보증인: 이병주
E20: 기업운전일반자금대출 | F20: KRW | G20: 21870000000 | H20: KRW | I20: 21870000000 | J20: 20221130 | K20: 20261128 | L20: 4.601 | M20: 00000000 | N20: 만기일시상환 | O20: 보증인: 이병주
E21: 기업운전일반자금대출 | F21: KRW | G21: 10000000000 | H21: KRW | I21: 10000000000 | J21: 20230628 | K21: 20260627 | L21: 4.419 | M21: 00000000 | N21: 만기일시상환 | O21: 부동산
E22: 기업운전일반자금대출 | F22: KRW | G22: 9250000000 | H22: KRW | I22: 9250000000 | J22: 20240430 | K22: 20260430 | L22: 4.359 | M22: 00000000 | N22: 만기일시상환 | O22: 부동산, 보증인: 이병주
E23: 기업시설일반자금대출 | F23: KRW | G23: 20200000000 | H23: KRW | I23: 20200000000 | J23: 20240430 | K23: 20260430 | L23: 4.005 | M23: 00000000 | N23: 만기일시상환 | O23: 부동산
E24: 기업운전일반자금대출 | F24: KRW | G24: 15000000000 | H24: KRW | I24: 15000000000 | J24: 20240603 | K24: 20260603 | L24: 4.699 | M24: 00000000 | N24: 만기일시상환 | O24: 부동산, 보증인: 이병주
E25: 기업운전일반자금대출 | F25: KRW | G25: 49500000000 | H25: KRW | I25: 49500000000 | J25: 20240430 | K25: 20260430 | L25: 4.329 | M25: 00000000 | N25: 만기일시상환 | O25: 유가증권
E26: 기업운전일반분할상환대출 | F26: KRW | G26: 10000000000 | H26: KRW | I26: 10000000000 | J26: 20250915 | K26: 20270915 | L26: 4.8 | M26: 00000000 | N26: 원금균등분할상환(최종불균등) | O26: 부동산, 보증인: 이병주
E27: 기업운전일반자금대출 | F27: KRW | G27: 20000000000 | H27: KRW | I27: 20000000000 | J27: 20250926 | K27: 20260926 | L27: 4.83 | M27: 00000000 | N27: 만기일시상환 | O27: 부동산, 유가증권, 보증인: 이병주
C28: BC-5 | D28: 신한은행 | E28: <기운>일반자금대출(일시상환) | F28: KRW | G28: 12800000000 | H28: KRW | I28: 12800000000 | J28: 20250627 | K28: 20260627 | L28: 4.51 | M28: 20251229 | N28: 일시상환 | O28: 404510514
C29: BC-6 | D29: 산업은행 | E29: 산업운영자금대출 | F29: KRW | G29: 0 | H29: KRW | I29: 20000000000 | J29: 20250626 | K29: 20260626 | L29: 4.17000 | M29: 20251226 | N29: 여신기간:1년(일시상환)
E30: 산업운영자금대출 | F30: KRW | G30: 0 | H30: KRW | I30: 10000000000 | J30: 20250626 | K30: 20260626 | L30: 4.17000 | M30: 20251226 | N30: 여신기간:1년(일시상환)
C31: BC-8 | D31: 한국수출입은행 | E31: 수입자금 | F31: KRW | G31: 0 | H31: KRW | I31: 5000000000 | J31: 20250922 | K31: 20260323 | L31: 변동4.310 | M31: 20251222 | N31: 일시 | O31: 신용-연대보증없음(100%)
C32: BC-14 | D32: NH투자증권 | E32: 보통담보대출 | F32: KRW | G32: 500000000 | H32: KRW | I32: 0 | N32: 만기일 일시상환
C33: BC-9 | D33: 한국증권금융 | E33: 일반담보대출(건별) | F33: KRW | G33: 23000000000 | H33: KRW | I33: 23000000000 | J33: 20210615 | K33: 20260615 | L33: 4.11 | M33: 20251229 | N33: 만기일시상환 | O33: 상세명세참조
E34: 일반담보대출(건별) | F34: KRW | G34: 35000000000 | H34: KRW | I34: 35000000000 | J34: 20240823 | K34: 20260615 | L34: 4.47 | M34: 20251229 | N34: 만기일시상환 | O34: 상세명세참조
C35: BC-27 | D35: 국민은행 홍콩 | E35: FRN | H35: USD | I35: 10000000 | J35: 20240909 | K35: 20260909 | L35: SOFR+1.15%
B38: 2) 금융조회서상 금액과 회사 장부상 금액을 대사하여 차이 여부를 확인함
C39: 구분 | D39: 통화 | E39: 조회서상 금액 | F39: 환율 (2024.12.31 현재) | G39: 원화환산액 | H39: 장부상 금액 | I39: 차이
C40: 단기차입금 | D40: KRW | E40: =SUMIFS($I$12:$I$19,$P$12:$P$19,C40,$H$12:$H$19,D40) -> 0 | F40: =VLOOKUP(D40,#REF!,2,FALSE) -> #REF! | G40: =+ROUND(E40*F40,0) -> #REF! | I40: =G40-H40 -> #REF!
C41: 단기차입금 | D41: USD | E41: =SUMIFS($I$12:$I$19,$P$12:$P$19,C41,$H$12:$H$19,D41) -> 0 | F41: =VLOOKUP(D41,#REF!,2,FALSE) -> #REF! | G41: =+ROUND(E41*F41,0) -> #REF! | I41: =G41-H41 -> #REF!
C42: S-Total | E42: =SUM(E40:E41) -> 0 | G42: =SUM(G40:G41) -> #REF! | H42: =SUM(H40:H41) -> 0 | I42: =+H42-G42 -> #REF!
C44: 장기차입금 | D44: KRW | E44: =SUMIFS($I$12:$I$19,$P$12:$P$19,C44,$H$12:$H$19,D44) -> 0 | F44: =VLOOKUP(D44,#REF!,2,FALSE) -> #REF! | G44: =+ROUND(E44*F44,0) -> #REF! | I44: =G44-H44 -> #REF!
C45: 장기차입금 | D45: USD | E45: =SUMIFS($I$12:$I$19,$P$12:$P$19,C45,$H$12:$H$19,D45) -> 0 | F45: =VLOOKUP(D45,#REF!,2,FALSE) -> #REF! | G45: =+ROUND(E45*F45,0) -> #REF! | I45: =G45-H45 -> #REF!
...

Sheet AC3. 파생상품
A1: ='AC2. 차입금'!A1 -> 코스맥스비티아이 주식회사 | L1: 작성자: | N1: 일자: | P1: 조서번호
A2: 금융조회서 요약(3) - 파생상품 | L2: 검토자: | N2: 일자: | P2: AC3
A3: 46022
A5: 1. 감사목적
B6: 회사 파생상품계약의 회계처리 적정성 검토
A8: 2. 감사절차
B9: 1) 금융조회서상 회사의 미결제파생상품계약을 요약 정리함
C10: 조서번호 | D10: 계약의 종류 | E10: 계약일 | F10: 한도액 | H10: 당행의 매입금액 | J10: 당행의 매도금액 | L10: 계약실행일/ 만기일 | M10: 약정환율/이자율/ 주가지수 등 | N10: 평가금액 | O10: 비고(결제조건 등) | P10: 회사 계정과목명
F11: 통화 | G11: 금액 | H11: 통화 | I11: 금액 | J11: 통화 | K11: 금액
C12: BC-1 | D12: 스왑 | E12: 20240903 | H12: KRW | I12: 13,416,000,000.00 | J12: USD | K12: 10000000 | L12: 20240909 | M12: 0.0000 | N12: ' | O12: RR: 4.410
B17: 2) 금융조회서상 파생상품 평가금액과 장부상 금액을 대사하여 차이 여부를 확인함
C18: 구분 | E18: 조회서상 금액 | F18: 장부상 금액 | G18: 차이
C19: 파생상품자산 | D19: 통화선도 | E19: =SUMIFS($N$12:$N$15,$P$12:$P$15,C19,$D$12:$D$15,D19) -> 0
C20: 파생상품자산 | D20: 이자율스왑 | E20: =SUMIFS($N$12:$N$15,$P$12:$P$15,C20,$D$12:$D$15,D20) -> 0
C21: S-Total | E21: =SUM(E19:E20) -> 0 | G21: =+F21-E21 -> 0
C23: 파생상품부채 | D23: 통화선도 | E23: =SUMIFS($N$12:$N$15,$P$12:$P$15,C23,$D$12:$D$15,D23) -> 0
C24: 파생상품부채 | D24: 이자율스왑 | E24: =SUMIFS($N$12:$N$15,$P$12:$P$15,C24,$D$12:$D$15,D24) -> 0
C25: S-Total | E25: =SUM(E23:E24) -> 0 | G25: =+F25-E25 -> 0
A27: 3. 결론
B28: 회사의 기말 파생상품 평가액은 회사 장부에 적절하게 반영됨

Sheet AC4. 지급보증
A1: ='AC3. 파생상품'!A1 -> 코스맥스비티아이 주식회사 | I1: 작성자: | K1: 일자: | M1: 조서번호
A2: 금융조회서 요약(4) - 지급보증 | I2: 검토자: | K2: 일자: | M2: AC4
A3: 46022
A5: 1. 감사목적
B6: 회사의 지급보증 등 약정사항 주석의 적정성 검토
A8: 2. 감사절차
B9: 1) 금융조회서상 회사가 제공받거나/제공한 지급보증 및 기타 약정사항을 요약 정리함
C10: ① 회사가 제공받은 지급보증 및 기타 약정사항
C11: 조서번호 | D11: 금융기관명 | E11: 내용 | F11: 한도액 | H11: 실행금액 | J11: 지급보증수수료율 | K11: 기간 | L11: 담보지급보증 | M11: 비고
F12: 통화 | G12: 금액 | H12: 통화 | I12: 금액
C13: BC-1 | D13: 국민은행 | E13: 기타외화지급보증서 발행분(R/G 포함) | F13: USD | G13: 0 | H13: USD | I13: 10000000 | K13: ' | L13: 9번항목참조
C14: BC-21 | D14: 서울보증보험 | E14: 지급 | H14: KRW | I14: 30,000,000
E15: 인허가 | H15: KRW | I15: 88,850,000
E16: 합계 | H16: KRW | I16: 118,850,000
C19: ② 회사가 타인에게 제공한 담보 및 연대보증
C20: 조서번호 | D20: 금융기관명 | E20: 연대보증 제공받은 자 | F20: 연대보증 대상 여신 | H20: 연대보증 한도 | J20: 담보제공한 자산 | K20: 비고
F21: 통화 | G21: 금액 | H21: 통화 | I21: 금액
C22: BC-1 | D22: 국민은행 | E22: 코스맥스엔비티(주) | F22: 일반운전자금 | H22: KRW | I22: 2400000000
E23: 코스맥스엔비티(주) | F23: 일반운전자금 | H23: KRW | I23: 1200000000
E24: 코스맥스엔비티(주) | F24: 일반운전자금 | H24: KRW | I24: 360000000
C25: BC-2 | D25: 기업은행 | E25: 코스맥스바이오(주) | F25: 할인어음 | H25: KRW | I25: 2400000000
E26: 코스맥스파마(주) | F26: 할인어음 | H26: KRW | I26: 1200000000
E27: 코스맥스파마(주) | F27: 외상매출채권담보대출 | H27: KRW | I27: 360000000
E28: 코스맥스바이오(주) | F28: 일반자금대출 | H28: KRW | I28: 8400000000
E29: 코스맥스바이오(주) | F29: 일반자금대출 | H29: KRW | I29: 2400000000
E30: 코스맥스엔비티 주식 | F30: 일반자금대출 | H30: KRW | I30: 12000000000
E31: 코스맥스파마(주) | F31: 일반자금대출 | H31: KRW | I31: 564000000
E32: 코스맥스파마(주) | F32: 기업구매자금대출 | H32: KRW | I32: 360000000
E33: 코스맥스파마(주) | F33: 일반자금대출 | H33: KRW | I33: 272400000
E34: 코스맥스파마(주) | F34: 할인어음 | H34: KRW | I34: 1200000000
E35: 코스맥스파마(주) | F35: 일반자금대출 | H35: KRW | I35: 833200000
E36: 코스맥스파마(주) | F36: 기업구매자금대출 | H36: KRW | I36: 600000000
C37: BC-23 | D37: 농협은행 | E37: 코스맥스바이오(주) | F37: 일반대출(01191037658 | H37: KRW | I37: 144000000 | J37: (4017235573)해당없음
E38: 코스맥스엔비티 주식 | F38: 일반대출(01191072670 | H38: KRW | I38: 2400000000 | J38: (4022401533)해당없음
E39: 코스맥스엔비티 주식 | F39: 일반대출(01191094703 | H39: KRW | I39: 6000000000 | J39: (4024532878)해당없음
E40: 코스맥스바이오(주) | F40: 어음할인(08291000175 | H40: KRW | I40: 144000000 | J40: (4017235667)해당없음
C41: BC-3 | D41: 우리은행 | E41: 코스맥스바이오주식회 | F41: 기업운전일반자금대출 | H41: KRW | I41: 1800000000 | J41: 보증인
E42: 코스맥스엔비티주식회 | F42: 기타외화지급보증（기 | H42: KRW | I42: 17218800000 | J42: 보증인
E43: 코스맥스엔비티주식회 | F43: 우량기업파워론－운 | H43: KRW | I43: 2040000000 | J43: 보증인
E44: 코스맥스엔비티주식회 | F44: 우리ＣＣＣＣ론－－－ | H44: KRW | I44: 12000000000 | J44: 보증인
...

Sheet AC5. 담보제공자산
A1: ='AC4. 지급보증'!A1 -> 코스맥스비티아이 주식회사 | G1: 작성자: | I1: 일자: | K1: 조서번호
A2: 금융조회서 요약(5) - 담보제공자산 | G2: 검토자: | I2: 일자: | K2: AC5
A3: 46022
A5: 1. 감사목적
B6: 회사의 담보제공자산 주석의 적정성 검토
A8: 2. 감사절차
B9: 1) 금융조회서상 회사의 담보제공자산을 요약 정리함
C10: ① 회사가 담보와 보증 등으로 제공한 자산
C11: 조서번호 | D11: 금융기관명 | E11: 구분 | F11: 담보보증의 내용 | G11: 소유자(제공자) | H11: 감정금액 | I11: 설정금액 | J11: 설정순위 | K11: 선순위 설정금액
C12: BC-1 | D12: 국민은행 | E12: 상장주식 | F12: ' | G12: 코스맥스비티아이(주) | H12: 20,171,880,000.00 | I12: 17,400,000,000.00 | J12: 1 | K12: 0.00
E13: 당연(필수)보증 | G13: 개인 | H13: 0.00 | I13: 1,100,000,000.00 | J13: 1 | K13: 0.00
E14: 당연(필수)보증 | G14: 개인 | H14: 0.00 | I14: 3,300,000,000.00 | J14: 1 | K14: 0.00
E15: 당연(필수)보증 | G15: 개인 | H15: 0.00 | I15: 5,500,000,000.00 | J15: 1 | K15: 0.00
E16: 당연(필수)보증 | F16: ' | G16: 개인 | H16: 0.00 | I16: USD 11,000,000.00 | J16: 1 | K16: 0.00
C17: BC-3 | D17: 우리은행 | E17: 보증인 | F17: (4017235573)해당없음 | G17: 코스맥스비티아이(주) | H17: 33058800000 | I17: 33058800000 | J17: 1 | K17: 0
C18: BC-4 | D18: 하나은행 | E18: 집합건물상가(독립적) | F18: 경기도 성남시 분당구 삼평동 622에프동101호 건물면적(1):386.15 | G18: 코스맥스비티아이(주) | H18: 2634000000 | I18: 12000000000 | J18: 3 | K18: '
E19: 집합건물상가(독립적) | F19: 경기도 성남시 분당구 삼평동 622에프동101호 건물면적(1):386.15 | G19: 코스맥스비티아이(주) | H19: 2634000000 | I19: 53340000000 | J19: 6 | K19: 51000000000
E20: 집합건물상가(독립적) | F20: 경기도 성남시 분당구 삼평동 622에프동102호 건물면적(1):161.16 | G20: 코스맥스비티아이(주) | H20: 1097000000 | I20: 12000000000 | J20: 3 | K20: '
E21: 집합건물상가(독립적) | F21: 경기도 성남시 분당구 삼평동 622에프동102호 건물면적(1):161.16 | G21: 코스맥스비티아이(주) | H21: 1097000000 | I21: 53340000000 | J21: 6 | K21: 51000000000
E22: 집합건물상가(독립적) | F22: 경기도 성남시 분당구 삼평동 622에프동201호 건물면적(1):1810.18 | G22: 코스맥스비티아이(주) | H22: 12337000000 | I22: 12000000000 | J22: 3 | K22: '
E23: 집합건물상가(독립적) | F23: 경기도 성남시 분당구 삼평동 622에프동201호 건물면적(1):1810.18 | G23: 코스맥스비티아이(주) | H23: 12337000000 | I23: 53340000000 | J23: 6 | K23: 51000000000
E24: 집합건물상가(독립적) | F24: 경기도 성남시 분당구 삼평동 622에프동301호 건물면적(1):1796.81 | G24: 코스맥스비티아이(주) | H24: 12245000000 | I24: 12000000000 | J24: 3 | K24: '
E25: 집합건물상가(독립적) | F25: 경기도 성남시 분당구 삼평동 622에프동301호 건물면적(1):1796.81 | G25: 코스맥스비티아이(주) | H25: 12245000000 | I25: 53340000000 | J25: 6 | K25: 51000000000
E26: 집합건물상가(독립적) | F26: 경기도 성남시 분당구 삼평동 622에프동401호 건물면적(1):1829.5 | G26: 코스맥스비티아이(주) | H26: 12471000000 | I26: 12000000000 | J26: 3 | K26: '
E27: 집합건물상가(독립적) | F27: 경기도 성남시 분당구 삼평동 622에프동401호 건물면적(1):1829.5 | G27: 코스맥스비티아이(주) | H27: 12471000000 | I27: 53340000000 | J27: 6 | K27: 51000000000
E28: 집합건물상가(독립적) | F28: 경기도 성남시 분당구 삼평동 622에프동501호 건물면적(1):1799.88 | G28: 코스맥스비티아이(주) | H28: 12267000000 | I28: 12000000000 | J28: 3 | K28: '
E29: 집합건물상가(독립적) | F29: 경기도 성남시 분당구 삼평동 622에프동501호 건물면적(1):1799.88 | G29: 코스맥스비티아이(주) | H29: 12267000000 | I29: 53340000000 | J29: 6 | K29: 51000000000
E30: 집합건물상가(독립적) | F30: 경기도 성남시 분당구 삼평동 622에프동601호 건물면적(1):1798.84 | G30: 코스맥스비티아이(주) | H30: 12263000000 | I30: 12000000000 | J30: 3 | K30: '
E31: 집합건물상가(독립적) | F31: 경기도 성남시 분당구 삼평동 622에프동601호 건물면적(1):1798.84 | G31: 코스맥스비티아이(주) | H31: 12263000000 | I31: 53340000000 | J31: 6 | K31: 51000000000
E32: 집합건물상가(독립적) | F32: 경기도 성남시 분당구 삼평동 622에프동701호 건물면적(1):1795.66 | G32: 코스맥스비티아이(주) | H32: 12240000000 | I32: 12000000000
E33: 집합건물상가(독립적) | F33: 경기도 성남시 분당구 삼평동 622에프동701호 건물면적(1):1795.66 | G33: 코스맥스비티아이(주) | H33: 12240000000 | I33: 53340000000
E34: 집합건물상가(독립적) | F34: 경기도 성남시 분당구 삼평동 622에프동801호 건물면적(1):1825.32 | G34: 코스맥스비티아이(주) | H34: 12444000000 | I34: 12000000000
E35: 집합건물상가(독립적) | F35: 경기도 성남시 분당구 삼평동 622에프동801호 건물면적(1):1825.32 | G35: 코스맥스비티아이(주) | H35: 12444000000 | I35: 53340000000
E36: 집합건물상가(독립적) | F36: 경기도 성남시 분당구 삼평동 622에프동901호 건물면적(1):1467.19 | G36: 코스맥스비티아이(주) | H36: 10002000000 | I36: 12000000000 | J36: 3 | K36: '
E37: 집합건물상가(독립적) | F37: 경기도 성남시 분당구 삼평동 622에프동901호 건물면적(1):1467.19 | G37: 코스맥스비티아이(주) | H37: 10002000000 | I37: 53340000000 | J37: 6 | K37: 51000000000
E38: 상장주식 | F38: 코스맥스(605000 건) | G38: 코스맥스비티아이(주) | H38: 70173950000 | I38: 59400000000 | J38: 3 | K38: '
E39: 상장주식 | F39: 코스맥스(605000 건) | G39: 코스맥스비티아이(주) | H39: 70173950000 | I39: 24000000000 | J39: 6 | K39: 51000000000
E40: 공장 | F40: 충청북도 증평군 도안면 노암리917 대지면적(1): 6714.8 건물면적(1): 4988.7 기 | G40: 코스맥스펫 주식회사 | H40: 7147248263 | I40: 10560000000 | J40: 3 | K40: '
E41: 공장 | F41: 충청북도 제천시 왕암동 922 대지면적(1): 23042.5 건물면적(1):13779.83 | G41: 코스맥스바이오(주) | H41: 2000 | I41: 10000000000 | J41: 6 | K41: 51000000000
E42: 보증인 | F42: 개인 | G42: 개인 | H42: - | I42: 4573200000 | J42: 1 | K42: '
...

Sheet AC6. 어음.수표
A1: ='AC5. 담보제공자산'!A1 -> 코스맥스비티아이 주식회사 | E1: 작성자: | H1: 일자: | J1: 조서번호
A2: 금융조회서 요약(6) - 어음. 수표 | E2: 검토자: | H2: 일자: | J2: AC6
A3: 46022
A5: 1. 감사목적
B6: 회사의 미회수 어음. 수표 검토를 통한 우발부채 등 검토
A8: 2. 감사절차
B9: 1) 금융조회서상 회사의 미회수 어음. 수표 등을 요약함
C10: ① 회사가 교부받은 어음과 수표
C11: - 전자어음
C12: 조서번호 | D12: 금융기관명 | E12: 교부일자 | G12: 매수
C14: 해당없음
C19: - 수표, 어음
C20: 조서번호 | D20: 금융기관명 | E20: 교부일자 | G20: 매수 | H20: 일련번호 | I20: 비고
C22: 해당없음
C26: ② 미결제 전자어음과 미회수된 어음. 수표
C27: - 미결제 전자어음
C28: 조서번호 | D28: 금융기관명 | E28: 만기일자 | G28: 금액 | H28: 일련번호 | I28: 비고
C30: 해당없음
C36: - 미회수 수표, 어음
C37: 조서번호 | D37: 금융기관명 | E37: 교부일자 | G37: 매수 | H37: 일련번호 | I37: 비고
C39: 해당없음
A44: 3. 결론
B45: 회사의 어음. 수표 관련 부채 및 관련 주석은 적정하게 반영됨

Sheet AC7. 보험가입내역
A1: ='AC6. 어음.수표'!A1 -> 코스맥스비티아이 주식회사 | G1: 작성자: | I1: 일자: | K1: 조서번호
A2: 금융조회서 요약(7) - 보험가입내역 | G2: 검토자: | I2: 일자: | K2: AC7
A3: 46022
A5: 1. 감사목적
B6: 회사의 보험 관련 비용 및 선급/미지급비용과 주석 공시 적정성 검토
A8: 2. 감사절차
B9: 1) 금융조회서상 회사의 보험거래내역을 요약함
C10: 조서번호 | D10: 금융기관명 | E10: 보험종류 | F10: 증권번호 | G10: 부보금액 | H10: 연간보험료 | I10: 보험기간 | K10: 권리제한 | L10: 수입보험료(USD) | M10: 선명 | N10: 누적적립금 | O10: 해약환급금 | P10: 연이자율 | Q10: 비고(연간보험료 이외)
I11: 시작일 | J11: 종료일
C12: BC-19 | D12: KB손해보험 | E12: No Fault Compensation Insurance | F12: 20258450627 | G12: 300,000,000 | H12: 2,034,000 | I12: 20251212 | J12: 20261211 | N12: 0 | O12: 0 | P12: 0
E13: KB업무용 | F13: 20258440287 | G13: 0 | H13: 1,265,530 | I13: 20251214 | J13: 20261214 | N13: 0 | O13: 0 | P13: 0
E14: KB업무용 | F14: 20247916943 | G14: 0 | H14: 0 | I14: 20241214 | J14: 20251214 | N14: 0 | O14: 0 | P14: 0
C15: BC-20 | D15: 한화손해보험 | E15: 한화 운전자상해보험 2504 | F15: LA20253782743000 | G15: 525410000 | H15: 122508 | I15: 20251002 | J15: 20301002 | N15: 0 | O15: 1390 | P15: 1.5
E16: 한화 운전자상해보험 2504 | F16: LA20253782778000 | G16: 520380000 | H16: 103734 | I16: 20251002 | J16: 20301002 | N16: 0 | O16: 1187 | P16: 1.5
E17: 한화 운전자상해보험 2504 | F17: LA20253784600000 | G17: 525410000 | H17: 110511 | I17: 20251002 | J17: 20301002 | N17: 0 | O17: 1255 | P17: 1.5
E18: 한화 운전자상해보험 2504 | F18: LA20253784620000 | G18: 525410000 | H18: 109020 | I18: 20251002 | J18: 20301002 | N18: 0 | O18: 1238 | P18: 1.5
E19: 한화 운전자상해보험 2504 | F19: LA20253782779000 | G19: 525410000 | H19: 119376 | I19: 20251002 | J19: 20301002 | N19: 0 | O19: 1368 | P19: 1.5
E20: 한화 운전자상해보험 2504 | F20: LA20253788560000 | G20: 460010000 | H20: 84783 | I20: 20251002 | J20: 20301002 | N20: 0 | O20: 935 | P20: 1.5
E21: 한화 운전자상해보험 2504 | F21: LA20253790569000 | G21: 390410000 | H21: 79554 | I21: 20251002 | J21: 20301002 | N21: 0 | O21: 877 | P21: 1.5
E22: 한화 운전자상해보험 2504 | F22: LA20253791841000 | G22: 522810000 | H22: 93732 | I22: 20251002 | J22: 20301002 | N22: 0 | O22: 1062 | P22: 1.5
E23: 한화 운전자상해보험 2504 | F23: LA20253791924000 | G23: 525410000 | H23: 112017 | I23: 20251002 | J23: 20301002 | N23: 0 | O23: 1271 | P23: 1.5
E24: 한화 운전자상해보험 2504 | F24: LA20253782773000 | G24: 533340000 | H24: 128589 | I24: 20251002 | J24: 20301002 | N24: 0 | O24: 1459 | P24: 1.5
E25: 한화 운전자상해보험 2504 | F25: LA20253792009000 | G25: 525410000 | H25: 114294 | I25: 20251002 | J25: 20301002 | N25: 0 | O25: 1311 | P25: 1.5
E26: 한화 운전자상해보험 2504 | F26: LA20253782776000 | G26: 626850000 | H26: 151959 | I26: 20251002 | J26: 20301002 | N26: 0 | O26: 1704 | P26: 1.5
E27: 한화 운전자상해보험 2504 | F27: LA20253782751000 | G27: 500280000 | H27: 96960 | I27: 20251002 | J27: 20301002 | N27: 0 | O27: 1121 | P27: 1.5
... E34: 한화 운전자상해보험 2504 | F34: LA20253782747000 | G34: 291850000 | H34: 91206 | I34: 20251002 | J34: 20301002 | N34: 0 | O34: 1025 | P34: 1.5
C35: BC-21 | D35: 메리츠화재해상보험 | E35: (무) 메리츠 재물보험 성공메이트2501 | F35: 6ADKD-1971 | G35: 0 | H35: 238491 | I35: 20250227 | J35: 20300227 | N35: 238480 | O35: 14163 | Q35: -11
C36: BC-30 | D36: 흥국화재 | E36: Package Insuranc Policy | F36: 12512730180000 | G36: 26329689846 | H36: 7971566 | I36: 20251214 | J36: 20261214
C37: BC-24 | D37: 현대해상화재보험 | E37: Products/Completed Operat | F37: F20240786542 | G37: 1412800000 | H37: 9692417 | I37: 20250101 | J37: 20260101 | N37: 9692417
C38: BC-25 | D38: 예별손해보험 | E38: Package Insuranc Policy | F38: 20240258411 | G38: 20215243773 | H38: 7810732 | I38: 20241107 | J38: 20251214
E39: MG재산종합보험(1) | F39: 20250063608 | G39: 5135784000 | H39: 10098200 | I39: 20250311 | J39: 20260311
E40: MG재산종합보험(1) | F40: 20240056896 | G40: 5135784000 | H40: 10746800 | I40: 20240311 | J40: 20250311
B43: 2) 금융조회서상 보험기간, 보험료 등을 고려하여 보험료, 관련 선급/미지급비용을 검토한 바 적정함
B44: 또한 회사의 보험가입내역 및 권리제한 등은 적정하게 공시됨
A46: 3. 결론
B47: 회사의 보험 관련 비용 및 선급/미지급비용과 주석 공시는 적정함

Sheet AC8. 리스거래
A1: ='AC7. 보험가입내역'!A1 -> 코스맥스비티아이 주식회사 | H1: 작성자: | J1: 일자: | L1: 조서번호
A2: 금융조회서 요약(8) - 리스 거래 | H2: 검토자: | J2: 일자: | L2: AC8
A3: 46022
A5: 1. 감사목적
B6: 회사의 리스 분류, 관련 비용 및 주석 공시 적정성 검토
A8: 2. 감사절차
B9: 1) 금융조회서상 회사의 리스거래내역을 요약함
C10: 조서번호 | D10: 금융기관명 | E10: 리스자산 내역 | F10: 계약번호 | G10: 보증금 | H10: 연간 리스료 | I10: 미상환리스료 | J10: 리스기간 | L10: 기타
J11: 시작일 | K11: 종료일
B19: 2) 금융조회서상 내용에 기초하여 리스 분류, 리스 관련 비용 인식 및 주석 공시가 적정한지 검토함
A21: 3. 결론
B22: 회사의 리스 분류, 관련 비용 및 주석 공시는 적정함

Sheet AC9. 거래내역
A1: 순번 | B1: 금융기관 | C1: 조회서 원본확인 필요

Sheet AC10. 추가사항
A2: BC-29 카일이삼제스퍼 | B2: 외상매출금 | C2: 20538000
